Workbook

Sheet 1. customers.csv
A1: customer_id | B1: name | C1: email | D1: phone | E1: city | F1: province | G1: registration_date | H1: gender | I1: age_group
A2: CUST0001 | B2: Andi Rahmawati | C2: andirahmawati229@yahoo.com | D2: 82118196001 | E2: Semarang | F2: Jawa Tengah | G2: 44673 | H2: Male | I2: 25-34
A3: CUST0002 | B3: Sari Sembiring | C3: sarisembiring226@gmail.com | D3: 85794026542 | E3: Semarang | F3: Jawa Tengah | G3: 44886 | H3: Female | I3: 18-24
A4: CUST0003 | B4: Bella Aprilia | C4: bellaaprilia271@gmail.com | D4: 81278161849 | E4: Tangerang | F4: Banten | G4: 45379 | H4: Female | I4: 18-24
A5: CUST0004 | B5: Shinta Hartono | C5: shintahartono82@outlook.com | D5: 82216475255 | E5: Semarang | F5: Jawa Tengah | G5: 45569 | H5: Female | I5: 25-34
A6: CUST0005 | B6: Maulana Hidayat | C6: maulanahidayat651@gmail.com | D6: 82183276483 | E6: Bekasi | F6: Jawa Barat | G6: 44311 | H6: Male | I6: 18-24
A7: CUST0006 | B7: Nadia Iskandar | C7: nadiaiskandar68@outlook.com | D7: 82295376724 | E7: Makassar | F7: Sulawesi Selatan | G7: 44702 | H7: Female | I7: 35-44
A8: CUST0007 | B8: Ratna Sari | C8: ratnasari920@gmail.com | D8: 87865328710 | E8: Medan | F8: Sumatera Utara | G8: 44510 | H8: Female | I8: 25-34
A9: CUST0008 | B9: Yoga Utami | C9: yogautami395@gmail.com | D9: 85697848018 | E9: Denpasar | F9: Bali | G9: 45509 | H9: Male | I9: 25-34
A10: CUST0009 | B10: Rani Simbolon | C10: ranisimbolon977@gmail.com | D10: 89648281489 | E10: Semarang | F10: Jawa Tengah | G10: 44510 | H10: Female | I10: 25-34
A11: CUST0010 | B11: Vera Hutapea | C11: verahutapea614@gmail.com | D11: 85370154303 | E11: Manado | F11: Sulawesi Utara | G11: 44358 | H11: Female | I11: 18-24
A12: CUST0011 | B12: Putri Sembiring | C12: putrisembiring132@yahoo.com | D12: 89578248963 | E12: Balikpapan | F12: Kalimantan Timur | G12: 45609 | H12: Female | I12: 18-24
A13: CUST0012 | B13: Shinta Ramadhan | C13: shintaramadhan922@gmail.com | D13: 85871331509 | E13: Balikpapan | F13: Kalimantan Timur | G13: 44668 | H13: Female | I13: 25-34
... A15: CUST0014 | B15: Hana Halim | C15: hanahalim97@yahoo.com | D15: 81365667010 | E15: Depok | F15: Jawa Barat | G15: 44891 | H15: Female | I15: 35-44
A16: CUST0015 | B16: Sari Permata | C16: saripermata460@gmail.com | E16: Medan | F16: Sumatera Utara | G16: 44300 | H16: Female | I16: 35-44
A17: CUST0016 | B17: Siti Nugroho | C17: sitinugroho171@yahoo.com | D17: 85677360260 | E17: Depok | F17: Jawa Barat | G17: 44740 | H17: Female | I17: 45+
A18: CUST0017 | B18: Wahyu Tanjung | C18: wahyutanjung678@gmail.com | D18: 89672343098 | E18: Surabaya | F18: Jawa Timur | G18: 44839 | H18: Male | I18: 18-24
A19: CUST0018 | B19: Dion Hutapea | C19: dionhutapea59@yahoo.com | D19: 85812191361 | E19: Manado | F19: Sulawesi Utara | G19: 44701 | H19: Male | I19: 25-34
A20: CUST0019 | B20: Rina Halim | C20: rinahalim579@gmail.com | D20: 85854353462 | E20: Malang | F20: Jawa Timur | G20: 45133 | H20: Female | I20: 25-34
A21: CUST0020 | B21: Joko Saputra | C21: jokosaputra637@gmail.com | D21: 87811838425 | E21: Bandung | F21: Jawa Barat | G21: 44697 | H21: Male | I21: 25-34
A22: CUST0021 | B22: Mawar Yulianti | C22: mawaryulianti827@gmail.com | D22: 89580841241 | E22: Medan | F22: Sumatera Utara | G22: 45330 | H22: Female | I22: 18-24
A23: CUST0022 | B23: Fitri Hasanah | C23: fitrihasanah704@yahoo.com | D23: 89548740164 | E23: Surabaya | F23: Jawa Timur | G23: 44204 | H23: Female | I23: 25-34
A24: CUST0023 | B24: Citra Maharani | C24: citramaharani565@gmail.com | D24: 89668011280 | E24: Tangerang | F24: Banten | G24: 45389 | H24: Female | I24: 25-34
A25: CUST0024 | B25: Sri Yulianti | C25: sriyulianti921@outlook.com | D25: 81253315869 | E25: Makassar | F25: Sulawesi Selatan | G25: 44681 | H25: Female | I25: 35-44
A26: CUST0025 | B26: Adi Halim | C26: adihalim184@gmail.com | D26: 89656342160 | E26: Pekanbaru | F26: Riau | G26: 44652 | H26: Male | I26: 18-24
A27: CUST0026 | B27: Nanda Yulianti | C27: nandayulianti229@yahoo.com | D27: 81236541458 | E27: Depok | F27: Jawa Barat | G27: 45588 | H27: Male | I27: 45+
A28: CUST0027 | B28: Dewi Kurniawan | C28: dewikurniawan183@outlook.com | D28: 87840196556 | E28: Pontianak | F28: Kalimantan Barat | G28: 45244 | H28: Female | I28: 18-24
... A80: CUST0079 | B80: Wulan Rahmawati | C80: wulanrahmawati649@gmail.com | D80: 87885698478 | E80: Pontianak | F80: Kalimantan Barat | G80: 45078 | H80: Female | I80: 18-24
A81: CUST0080 | B81: Maulana Tarigan | C81: maulanatarigan441@yahoo.com | E81: Bogor | F81: Jawa Barat | G81: 44837 | H81: Male | I81: 35-44
A82: CUST0081 | B82: Indah Pohan | C82: indahpohan94@gmail.com | D82: 81316152809 | E82: Balikpapan | F82: Kalimantan Timur | G82: 45347 | H82: Female | I82: 25-34
A83: CUST0082 | B83: Bella Tanjung | C83: bellatanjung992@gmail.com | D83: 85294519832 | E83: Pekanbaru | F83: Riau | G83: 44656 | H83: Female | I83: 35-44
A84: CUST0083 | B84: Melati Ramadhan | C84: melatiramadhan781@gmail.com | D84: 85293689980 | E84: Pontianak | F84: Kalimantan Barat | G84: 45544 | H84: Female | I84: 35-44
A85: CUST0084 | B85: Mira Rahmawati | C85: mirarahmawati944@outlook.com | D85: 85350229612 | E85: Jakarta | F85: DKI Jakarta | G85: 44384 | H85: Female | I85: 35-44
A86: CUST0085 | B86: Mega Simbolon | C86: megasimbolon162@outlook.com | D86: 85345991022 | E86: Pontianak | F86: Kalimantan Barat | G86: 44298 | H86: Female | I86: 35-44
A87: CUST0086 | B87: Shinta Tanjung | C87: shintatanjung622@gmail.com | D87: 85764381561 | E87: Malang | F87: Jawa Timur | G87: 45585 | H87: Female | I87: 35-44
A88: CUST0087 | B88: Shinta Yulianti | C88: shintayulianti226@gmail.com | D88: 85690034324 | E88: Malang | F88: Jawa Timur | G88: 44868 | H88: Female | I88: 18-24
A89: CUST0088 | B89: Lia Wardani | C89: liawardani390@yahoo.com | D89: 85838851606 | E89: Jakarta | F89: DKI Jakarta | G89: 45138 | H89: Female | I89: 45+
A90: CUST0089 | B90: Irfan Tanjung | C90: irfantanjung415@gmail.com | D90: 89664160529 | E90: Padang | F90: Sumatera Barat | G90: 45609 | H90: Male | I90: 45+
A91: CUST0090 | B91: Lina Suryadi | C91: linasuryadi604@gmail.com | D91: 85681645352 | E91: Bandung | F91: Jawa Barat | G91: 45242 | H91: Female | I91: 25-34
A92: CUST0091 | B92: Sari Aprilia | C92: sariaprilia745@outlook.com | D92: 89523124329 | E92: Makassar | F92: Sulawesi Selatan | G92: 45539 | H92: Female | I92: 18-24
...

Sheet 1. customers_clean.csv
A1: customer_id | B1: name | C1: email | D1: phone | E1: city | F1: province | G1: registration_date | H1: gender | I1: age_group
A2: CUST0001 | B2: Andi Rahmawati | C2: andirahmawati229@yahoo.com | D2: 82118196001 | E2: Semarang | F2: Jawa Tengah | G2: 44673 | H2: Male | I2: 25-34
A3: CUST0002 | B3: Sari Sembiring | C3: sarisembiring226@gmail.com | D3: 85794026542 | E3: Semarang | F3: Jawa Tengah | G3: 44886 | H3: Female | I3: 18-24
A4: CUST0003 | B4: Bella Aprilia | C4: bellaaprilia271@gmail.com | D4: 81278161849 | E4: Tangerang | F4: Banten | G4: 45379 | H4: Female | I4: 18-24
A5: CUST0004 | B5: Shinta Hartono | C5: shintahartono82@outlook.com | D5: 82216475255 | E5: Semarang | F5: Jawa Tengah | G5: 45569 | H5: Female | I5: 25-34
A6: CUST0005 | B6: Maulana Hidayat | C6: maulanahidayat651@gmail.com | D6: 82183276483 | E6: Bekasi | F6: Jawa Barat | G6: 44311 | H6: Male | I6: 18-24
A7: CUST0006 | B7: Nadia Iskandar | C7: nadiaiskandar68@outlook.com | D7: 82295376724 | E7: Makassar | F7: Sulawesi Selatan | G7: 44702 | H7: Female | I7: 35-44
A8: CUST0007 | B8: Ratna Sari | C8: ratnasari920@gmail.com | D8: 87865328710 | E8: Medan | F8: Sumatera Utara | G8: 44510 | H8: Female | I8: 25-34
A9: CUST0008 | B9: Yoga Utami | C9: yogautami395@gmail.com | D9: 85697848018 | E9: Denpasar | F9: Bali | G9: 45509 | H9: Male | I9: 25-34
A10: CUST0009 | B10: Rani Simbolon | C10: ranisimbolon977@gmail.com | D10: 89648281489 | E10: Semarang | F10: Jawa Tengah | G10: 44510 | H10: Female | I10: 25-34
A11: CUST0010 | B11: Vera Hutapea | C11: verahutapea614@gmail.com | D11: 85370154303 | E11: Manado | F11: Sulawesi Utara | G11: 44358 | H11: Female | I11: 18-24
A12: CUST0011 | B12: Putri Sembiring | C12: putrisembiring132@yahoo.com | D12: 89578248963 | E12: Balikpapan | F12: Kalimantan Timur | G12: 45609 | H12: Female | I12: 18-24
A13: CUST0012 | B13: Shinta Ramadhan | C13: shintaramadhan922@gmail.com | D13: 85871331509 | E13: Balikpapan | F13: Kalimantan Timur | G13: 44668 | H13: Female | I13: 25-34
... A15: CUST0014 | B15: Hana Halim | C15: hanahalim97@yahoo.com | D15: 81365667010 | E15: Depok | F15: Jawa Barat | G15: 44891 | H15: Female | I15: 35-44
A16: CUST0015 | B16: Sari Permata | C16: saripermata460@gmail.com | D16: Tidak Ada | E16: Medan | F16: Sumatera Utara | G16: 44300 | H16: Female | I16: 35-44
A17: CUST0016 | B17: Siti Nugroho | C17: sitinugroho171@yahoo.com | D17: 85677360260 | E17: Depok | F17: Jawa Barat | G17: 44740 | H17: Female | I17: 45+
A18: CUST0017 | B18: Wahyu Tanjung | C18: wahyutanjung678@gmail.com | D18: 89672343098 | E18: Surabaya | F18: Jawa Timur | G18: 44839 | H18: Male | I18: 18-24
A19: CUST0018 | B19: Dion Hutapea | C19: dionhutapea59@yahoo.com | D19: 85812191361 | E19: Manado | F19: Sulawesi Utara | G19: 44701 | H19: Male | I19: 25-34
A20: CUST0019 | B20: Rina Halim | C20: rinahalim579@gmail.com | D20: 85854353462 | E20: Malang | F20: Jawa Timur | G20: 45133 | H20: Female | I20: 25-34
A21: CUST0020 | B21: Joko Saputra | C21: jokosaputra637@gmail.com | D21: 87811838425 | E21: Bandung | F21: Jawa Barat | G21: 44697 | H21: Male | I21: 25-34
A22: CUST0021 | B22: Mawar Yulianti | C22: mawaryulianti827@gmail.com | D22: 89580841241 | E22: Medan | F22: Sumatera Utara | G22: 45330 | H22: Female | I22: 18-24
A23: CUST0022 | B23: Fitri Hasanah | C23: fitrihasanah704@yahoo.com | D23: 89548740164 | E23: Surabaya | F23: Jawa Timur | G23: 44204 | H23: Female | I23: 25-34
A24: CUST0023 | B24: Citra Maharani | C24: citramaharani565@gmail.com | D24: 89668011280 | E24: Tangerang | F24: Banten | G24: 45389 | H24: Female | I24: 25-34
A25: CUST0024 | B25: Sri Yulianti | C25: sriyulianti921@outlook.com | D25: 81253315869 | E25: Makassar | F25: Sulawesi Selatan | G25: 44681 | H25: Female | I25: 35-44
A26: CUST0025 | B26: Adi Halim | C26: adihalim184@gmail.com | D26: 89656342160 | E26: Pekanbaru | F26: Riau | G26: 44652 | H26: Male | I26: 18-24
A27: CUST0026 | B27: Nanda Yulianti | C27: nandayulianti229@yahoo.com | D27: 81236541458 | E27: Depok | F27: Jawa Barat | G27: 45588 | H27: Male | I27: 45+
A28: CUST0027 | B28: Dewi Kurniawan | C28: dewikurniawan183@outlook.com | D28: 87840196556 | E28: Pontianak | F28: Kalimantan Barat | G28: 45244 | H28: Female | I28: 18-24
... A80: CUST0079 | B80: Wulan Rahmawati | C80: wulanrahmawati649@gmail.com | D80: 87885698478 | E80: Pontianak | F80: Kalimantan Barat | G80: 45078 | H80: Female | I80: 18-24
A81: CUST0080 | B81: Maulana Tarigan | C81: maulanatarigan441@yahoo.com | D81: Tidak Ada | E81: Bogor | F81: Jawa Barat | G81: 44837 | H81: Male | I81: 35-44
A82: CUST0081 | B82: Indah Pohan | C82: indahpohan94@gmail.com | D82: 81316152809 | E82: Balikpapan | F82: Kalimantan Timur | G82: 45347 | H82: Female | I82: 25-34
A83: CUST0082 | B83: Bella Tanjung | C83: bellatanjung992@gmail.com | D83: 85294519832 | E83: Pekanbaru | F83: Riau | G83: 44656 | H83: Female | I83: 35-44
A84: CUST0083 | B84: Melati Ramadhan | C84: melatiramadhan781@gmail.com | D84: 85293689980 | E84: Pontianak | F84: Kalimantan Barat | G84: 45544 | H84: Female | I84: 35-44
A85: CUST0084 | B85: Mira Rahmawati | C85: mirarahmawati944@outlook.com | D85: 85350229612 | E85: Jakarta | F85: DKI Jakarta | G85: 44384 | H85: Female | I85: 35-44
A86: CUST0085 | B86: Mega Simbolon | C86: megasimbolon162@outlook.com | D86: 85345991022 | E86: Pontianak | F86: Kalimantan Barat | G86: 44298 | H86: Female | I86: 35-44
A87: CUST0086 | B87: Shinta Tanjung | C87: shintatanjung622@gmail.com | D87: 85764381561 | E87: Malang | F87: Jawa Timur | G87: 45585 | H87: Female | I87: 35-44
A88: CUST0087 | B88: Shinta Yulianti | C88: shintayulianti226@gmail.com | D88: 85690034324 | E88: Malang | F88: Jawa Timur | G88: 44868 | H88: Female | I88: 18-24
A89: CUST0088 | B89: Lia Wardani | C89: liawardani390@yahoo.com | D89: 85838851606 | E89: Jakarta | F89: DKI Jakarta | G89: 45138 | H89: Female | I89: 45+
A90: CUST0089 | B90: Irfan Tanjung | C90: irfantanjung415@gmail.com | D90: 89664160529 | E90: Padang | F90: Sumatera Barat | G90: 45609 | H90: Male | I90: 45+
A91: CUST0090 | B91: Lina Suryadi | C91: linasuryadi604@gmail.com | D91: 85681645352 | E91: Bandung | F91: Jawa Barat | G91: 45242 | H91: Female | I91: 25-34
A92: CUST0091 | B92: Sari Aprilia | C92: sariaprilia745@outlook.com | D92: 89523124329 | E92: Makassar | F92: Sulawesi Selatan | G92: 45539 | H92: Female | I92: 18-24
...

Sheet 2. order_items.csv
A1: item_id | B1: order_id | C1: product_id | D1: quantity | E1: unit_price_idr | F1: subtotal_idr
A2: ITM000001 | B2: ORD000001 | C2: PRD070 | D2: 1 | E2: 349000 | F2: 349000
A3: ITM000002 | B3: ORD000001 | C3: PRD001 | D3: 2 | E3: 599000 | F3: 1198000
A4: ITM000003 | B4: ORD000001 | C4: PRD148 | D4: 1 | E4: 449000 | F4: 449000
A5: ITM000004 | B5: ORD000002 | C5: PRD086 | D5: 1 | E5: 329000 | F5: 329000
A6: ITM000005 | B6: ORD000002 | C6: PRD258 | D6: 1 | E6: 129000 | F6: 129000
A7: ITM000006 | B7: ORD000002 | C7: PRD256 | D7: 1 | E7: 49000 | F7: 49000
A8: ITM000007 | B8: ORD000003 | C8: PRD076 | D8: 1 | E8: 199000 | F8: 199000
A9: ITM000008 | B9: ORD000004 | C9: PRD205 | D9: 1 | E9: 119000 | F9: 119000
A10: ITM000009 | B10: ORD000005 | C10: PRD239 | D10: 2 | E10: 179000 | F10: 358000
A11: ITM000010 | B11: ORD000006 | C11: PRD170 | D11: 1 | E11: 349000 | F11: 349000
A12: ITM000011 | B12: ORD000007 | C12: PRD013 | D12: 1 | E12: 149000 | F12: 149000
A13: ITM000012 | B13: ORD000007 | C13: PRD230 | D13: 2 | E13: 129000 | F13: 258000
... A4987: ITM004986 | B4987: ORD003000 | C4987: PRD117 | D4987: 1 | E4987: 49000 | F4987: 49000

Sheet 2. order_items_clean.csv
A1: item_id | B1: order_id | C1: product_id | D1: quantity | E1: unit_price_idr | F1: subtotal_idr
A2: ITM000001 | B2: ORD000001 | C2: PRD070 | D2: 1 | E2: 349000 | F2: 349000
A3: ITM000002 | B3: ORD000001 | C3: PRD001 | D3: 2 | E3: 599000 | F3: 1198000
A4: ITM000003 | B4: ORD000001 | C4: PRD148 | D4: 1 | E4: 449000 | F4: 449000
A5: ITM000004 | B5: ORD000002 | C5: PRD086 | D5: 1 | E5: 329000 | F5: 329000
A6: ITM000005 | B6: ORD000002 | C6: PRD258 | D6: 1 | E6: 129000 | F6: 129000
A7: ITM000006 | B7: ORD000002 | C7: PRD256 | D7: 1 | E7: 49000 | F7: 49000
A8: ITM000007 | B8: ORD000003 | C8: PRD076 | D8: 1 | E8: 199000 | F8: 199000
A9: ITM000008 | B9: ORD000004 | C9: PRD205 | D9: 1 | E9: 119000 | F9: 119000
A10: ITM000009 | B10: ORD000005 | C10: PRD239 | D10: 2 | E10: 179000 | F10: 358000
A11: ITM000010 | B11: ORD000006 | C11: PRD170 | D11: 1 | E11: 349000 | F11: 349000
A12: ITM000011 | B12: ORD000007 | C12: PRD013 | D12: 1 | E12: 149000 | F12: 149000
A13: ITM000012 | B13: ORD000007 | C13: PRD230 | D13: 2 | E13: 129000 | F13: 258000
... A4987: ITM004986 | B4987: ORD003000 | C4987: PRD117 | D4987: 1 | E4987: 49000 | F4987: 49000

Sheet 3. orders.csv
A1: order_id | B1: customer_id | C1: order_date | D1: total_amount_idr | E1: shipping_city | F1: shipping_province | G1: shipping_cost_idr | H1: payment_method | I1: order_status | J1: promo_code | K1: discount_amount_idr | L1: courier
A2: ORD000001 | B2: CUST0474 | C2: 45008 | D2: 1951591 | E2: Banjarmasin | F2: Kalimantan Selatan | G2: 32066 | H2: Transfer Bank | I2: shipped | J2: WEEKEND25 | K2: 44409 | L2: JNE
A3: ORD000002 | B3: CUST0478 | C3: 45714 | D3: 507000 | E3: Palembang | F3: Sumatera Selatan | G3: 33769 | H3: Kartu Kredit | I3: delivered | L3: JNE
A4: ORD000003 | B4: CUST0306 | C4: 44755 | D4: 199000 | E4: Tangerang | F4: Banten | G4: 12060 | H4: Transfer Bank | I4: delivered | L4: SiCepat
A5: ORD000004 | B5: CUST0777 | C5: 45622 | D5: 119000 | E5: Medan | F5: Sumatera Utara | G5: 29005 | H5: Transfer Bank | I5: cancelled | L5: Anteraja
A6: ORD000005 | B6: CUST0210 | C6: 45138 | D6: 358000 | E6: Bandung | F6: Jawa Barat | G6: 11192 | H6: Kartu Kredit | I6: cancelled | L6: JNE
A7: ORD000006 | B7: CUST0444 | C7: 44693 | D7: 349000 | E7: Balikpapan | F7: Kalimantan Timur | G7: 37816 | H7: Transfer Bank | I7: returned | L7: SiCepat
A8: ORD000007 | B8: CUST0170 | C8: 44597 | D8: 407000 | E8: Bekasi | F8: Jawa Barat | G8: 13600 | H8: Transfer Bank | I8: delivered | L8: JNE
A9: ORD000008 | B9: CUST0637 | C9: 45079 | D9: 954364 | E9: Manado | F9: Sulawesi Utara | G9: 34020 | H9: Kartu Kredit | I9: processing | J9: WEEKEND25 | K9: 31636 | L9: J&T
A10: ORD000009 | B10: CUST0677 | C10: 45650 | D10: 230288 | E10: Surabaya | F10: Jawa Timur | G10: 13179 | H10: Transfer Bank | I10: cancelled | J10: HARBOLNAS22 | K10: 18712 | L10: JNE
A11: ORD000010 | B11: CUST0200 | C11: 45030 | D11: 264669 | E11: Pontianak | F11: Kalimantan Barat | G11: 30484 | H11: GoPay | I11: delivered | J11: HARI BELANJA | K11: 14331 | L11: Pos Indonesia
A12: ORD000011 | B12: CUST0225 | C12: 45015 | D12: 226000 | E12: Bekasi | F12: Jawa Barat | G12: 9935 | H12: Transfer Bank | I12: delivered | L12: Anteraja
A13: ORD000012 | B13: CUST0760 | C13: 45241 | D13: 251162 | E13: Balikpapan | F13: Kalimantan Timur | G13: 40940 | H13: OVO | I13: shipped | J13: HARI BELANJA | K13: 27838 | L13: J&T
A14: ORD000013 | B14: CUST0337 | C14: 45704 | D14: 199000 | E14: Depok | F14: Jawa Barat | G14: 9420 | H14: QRIS | I14: delivered | L14: Anteraja
A15: ORD000014 | B15: CUST0225 | C15: 45397 | D15: 334654 | E15: Medan | F15: Sumatera Utara | G15: 36425 | H15: GoPay | I15: delivered | J15: HARI BELANJA | K15: 14346 | L15: SiCepat
A16: ORD000015 | B16: CUST0794 | C16: 44940 | D16: 2537438 | E16: Pekanbaru | F16: Riau | G16: 29080 | H16: Transfer Bank | I16: delivered | J16: NEWUSER | K16: 36562 | L16: JNE
A17: ORD000016 | B17: CUST0441 | C17: 45420 | D17: 1746000 | E17: Manado | F17: Sulawesi Utara | G17: 34701 | H17: GoPay | I17: delivered | L17: J&T
A18: ORD000017 | B18: CUST0715 | C18: 45292 | D18: 355448 | E18: Semarang | F18: Jawa Tengah | G18: 12267 | H18: Transfer Bank | I18: returned | J18: RAMADAN23 | K18: 12552 | L18: J&T
A19: ORD000018 | B19: CUST0597 | C19: 44581 | D19: 119000 | E19: Bogor | F19: Jawa Barat | G19: 11574 | H19: Kartu Kredit | I19: cancelled | L19: SiCepat
A20: ORD000019 | B20: CUST0539 | C20: 44844 | D20: 247331 | E20: Balikpapan | F20: Kalimantan Timur | G20: 37574 | H20: OVO | I20: delivered | J20: FLASHSALE | K20: 20669 | L20: SiCepat
A21: ORD000020 | B21: CUST0712 | C21: 45150 | D21: 377322 | E21: Malang | F21: Jawa Timur | G21: 16405 | H21: OVO | I21: processing | J21: RAMADAN23 | K21: 19678 | L21: J&T
A22: ORD000021 | B22: CUST0111 | C22: 45662 | D22: 748000 | E22: Pontianak | F22: Kalimantan Barat | G22: 32628 | H22: Kartu Kredit | I22: shipped | L22: J&T
A23: ORD000022 | B23: CUST0566 | C23: 45442 | D23: 279000 | E23: Malang | F23: Jawa Timur | G23: 21336 | H23: GoPay | I23: delivered | L23: JNE
A24: ORD000023 | B24: CUST0259 | C24: 45153 | D24: 625000 | E24: Banjarmasin | F24: Kalimantan Selatan | G24: 34512 | H24: Kartu Kredit | I24: cancelled | L24: J&T
A25: ORD000024 | B25: CUST0189 | C25: 44651 | D25: 744000 | E25: Tangerang | F25: Banten | G25: 9763 | H25: GoPay | I25: returned | L25: JNE
A26: ORD000025 | B26: CUST0790 | C26: 44735 | D26: 288000 | E26: Balikpapan | F26: Kalimantan Timur | G26: 40074 | H26: GoPay | I26: delivered | L26: J&T
A27: ORD000026 | B27: CUST0755 | C27: 45429 | D27: 549000 | E27: Tangerang | F27: Banten | G27: 13331 | H27: QRIS | I27: shipped | L27: SiCepat
A28: ORD000027 | B28: CUST0561 | C28: 45140 | D28: 1098000 | E28: Yogyakarta | F28: DI Yogyakarta | G28: 13146 | H28: GoPay | I28: shipped | L28: SiCepat
A29: ORD000028 | B29: CUST0624 | C29: 45470 | D29: 408558 | E29: Balikpapan | F29: Kalimantan Timur | G29: 37360 | H29: Transfer Bank | I29: cancelled | J29: NEWUSER | K29: 39442 | L29: Anteraja
A30: ORD000029 | B30: CUST0245 | C30: 45109 | D30: 298000 | E30: Denpasar | F30: Bali | G30: 28769 | H30: Kartu Kredit | I30: delivered | L30: J&T
A31: ORD000030 | B31: CUST0566 | C31: 44985 | D31: 329000 | E31: Malang | F31: Jawa Timur | G31: 17186 | H31: OVO | I31: delivered | L31: J&T
A32: ORD000031 | B32: CUST0492 | C32: 44650 | D32: 200075 | E32: Pekanbaru | F32: Riau | G32: 26230 | H32: Transfer Bank | I32: delivered | J32: RAMADAN23 | K32: 28925 | L32: JNE
A33: ORD000032 | B33: CUST0317 | C33: 45660 | D33: 624526 | E33: Medan | F33: Sumatera Utara | G33: 38976 | H33: QRIS | I33: returned | J33: HARI BELANJA | K33: 43474 | L33: JNE
A34: ORD000033 | B34: CUST0126 | C34: 45208 | D34: 79000 | E34: Depok | F34: Jawa Barat | G34: 11918 | H34: Kartu Kredit | I34: delivered | L34: J&T
A35: ORD000034 | B35: CUST0636 | C35: 45325 | D35: 279000 | E35: Yogyakarta | F35: DI Yogyakarta | G35: 15802 | H35: Transfer Bank | I35: processing | L35: J&T
A36: ORD000035 | B36: CUST0775 | C36: 45194 | D36: 896000 | E36: Semarang | F36: Jawa Tengah | G36: 13372 | H36: Transfer Bank | I36: shipped | L36: SiCepat
A37: ORD000036 | B37: CUST0571 | C37: 45484 | D37: 548000 | E37: Manado | F37: Sulawesi Utara | G37: 35262 | H37: Kartu Kredit | I37: delivered | L37: JNE
A38: ORD000037 | B38: CUST0323 | C38: 45327 | D38: 218221 | E38: Pontianak | F38: Kalimantan Barat | G38: 36528 | H38: OVO | I38: delivered | J38: HARBOLNAS22 | K38: 30779 | L38: JNE
A39: ORD000038 | B39: CUST0252 | C39: 45117 | D39: 798000 | E39: Balikpapan | F39: Kalimantan Timur | G39: 31746 | H39: Transfer Bank | I39: delivered | L39: Pos Indonesia
A40: ORD000039 | B40: CUST0288 | C40: 45110 | D40: 329000 | E40: Tangerang | F40: Banten | G40: 9615 | H40: GoPay | I40: shipped | L40: J&T
...

Sheet 3. orders_clean.csv
A1: order_id | B1: customer_id | C1: order_date | D1: total_amount_idr | E1: shipping_city | F1: shipping_province | G1: shipping_cost_idr | H1: payment_method | I1: order_status | J1: is_lost_revenue | K1: promo_code | L1: discount_amount_idr | M1: courier
A2: ORD000001 | B2: CUST0474 | C2: 45008 | D2: 1951591 | E2: Banjarmasin | F2: Kalimantan Selatan | G2: 32066 | H2: Transfer Bank | I2: shipped | J2: =IF(OR(I2="cancelled",I2="returned"),TRUE,FALSE) -> FALSE | K2: WEEKEND25 | L2: 44409 | M2: JNE
A3: ORD000002 | B3: CUST0478 | C3: 45714 | D3: 507000 | E3: Palembang | F3: Sumatera Selatan | G3: 33769 | H3: Kartu Kredit | I3: delivered | J3: =IF(OR(I3="cancelled",I3="returned"),TRUE,FALSE) -> FALSE | K3: No Promo | L3: 0 | M3: JNE
A4: ORD000003 | B4: CUST0306 | C4: 44755 | D4: 199000 | E4: Tangerang | F4: Banten | G4: 12060 | H4: Transfer Bank | I4: delivered | J4: =IF(OR(I4="cancelled",I4="returned"),TRUE,FALSE) -> FALSE | K4: No Promo | L4: 0 | M4: SiCepat
A5: ORD000004 | B5: CUST0777 | C5: 45622 | D5: 119000 | E5: Medan | F5: Sumatera Utara | G5: 29005 | H5: Transfer Bank | I5: cancelled | J5: =IF(OR(I5="cancelled",I5="returned"),TRUE,FALSE) -> TRUE | K5: No Promo | L5: 0 | M5: Anteraja
A6: ORD000005 | B6: CUST0210 | C6: 45138 | D6: 358000 | E6: Bandung | F6: Jawa Barat | G6: 11192 | H6: Kartu Kredit | I6: cancelled | J6: =IF(OR(I6="cancelled",I6="returned"),TRUE,FALSE) -> TRUE | K6: No Promo | L6: 0 | M6: JNE
A7: ORD000006 | B7: CUST0444 | C7: 44693 | D7: 349000 | E7: Balikpapan | F7: Kalimantan Timur | G7: 37816 | H7: Transfer Bank | I7: returned | J7: =IF(OR(I7="cancelled",I7="returned"),TRUE,FALSE) -> TRUE | K7: No Promo | L7: 0 | M7: SiCepat
A8: ORD000007 | B8: CUST0170 | C8: 44597 | D8: 407000 | E8: Bekasi | F8: Jawa Barat | G8: 13600 | H8: Transfer Bank | I8: delivered | J8: =IF(OR(I8="cancelled",I8="returned"),TRUE,FALSE) -> FALSE | K8: No Promo | L8: 0 | M8: JNE
A9: ORD000008 | B9: CUST0637 | C9: 45079 | D9: 954364 | E9: Manado | F9: Sulawesi Utara | G9: 34020 | H9: Kartu Kredit | I9: processing | J9: =IF(OR(I9="cancelled",I9="returned"),TRUE,FALSE) -> FALSE | K9: WEEKEND25 | L9: 31636 | M9: J&T
A10: ORD000009 | B10: CUST0677 | C10: 45650 | D10: 230288 | E10: Surabaya | F10: Jawa Timur | G10: 13179 | H10: Transfer Bank | I10: cancelled | J10: =IF(OR(I10="cancelled",I10="returned"),TRUE,FALSE) -> TRUE | K10: HARBOLNAS22 | L10: 18712 | M10: JNE
A11: ORD000010 | B11: CUST0200 | C11: 45030 | D11: 264669 | E11: Pontianak | F11: Kalimantan Barat | G11: 30484 | H11: GoPay | I11: delivered | J11: =IF(OR(I11="cancelled",I11="returned"),TRUE,FALSE) -> FALSE | K11: HARI BELANJA | L11: 14331 | M11: Pos Indonesia
A12: ORD000011 | B12: CUST0225 | C12: 45015 | D12: 226000 | E12: Bekasi | F12: Jawa Barat | G12: 9935 | H12: Transfer Bank | I12: delivered | J12: =IF(OR(I12="cancelled",I12="returned"),TRUE,FALSE) -> FALSE | K12: No Promo | L12: 0 | M12: Anteraja
A13: ORD000012 | B13: CUST0760 | C13: 45241 | D13: 251162 | E13: Balikpapan | F13: Kalimantan Timur | G13: 40940 | H13: OVO | I13: shipped | J13: =IF(OR(I13="cancelled",I13="returned"),TRUE,FALSE) -> FALSE | K13: HARI BELANJA | L13: 27838 | M13: J&T
... A3001: ORD003000 | B3001: CUST0556 | C3001: 45434 | D3001: 38484 | E3001: Depok | F3001: Jawa Barat | G3001: 13709 | H3001: OVO | I3001: returned | J3001: =IF(OR(I3001="cancelled",I3001="returned"),TRUE,FALSE) -> TRUE | K3001: RAMADAN23 | L3001: 10516 | M3001: J&T

Sheet 4. products.csv
A1: product_id | B1: name | C1: category | D1: sub_category | E1: price_idr | F1: stock | G1: brand | H1: material | I1: avg_rating
A2: PRD001 | B2: Dress Bodycon Pesona Indo | C2: dress | D2: Atasan Wanita | E2: 599000 | F2: 0 | G2: Pesona Indo | H2: Linen | I2: 5
A3: PRD002 | B3: Kaos Oversize BajuKita | C3: T-Shirt | D3: Atasan Pria | E3: 329000 | F3: 239 | G3: BajuKita | H3: Cotton 100% | I3: 3.7
A4: PRD003 | B4: Dress Maxi Polos Senja Wear | C4: dress | D4: Atasan Wanita | E4: 349000 | F4: 80 | G4: Senja Wear | H4: Cotton-Polyester | I4: 4.7
A5: PRD004 | B5: Ikat Pinggang Kulit Cendana Co | C5: Accessories | D5: Aksesoris | E5: 199000 | F5: 309 | G5: Cendana Co | H5: Denim | I5: 4.6
A6: PRD005 | B6: Dress Bodycon Senja Wear | C6: dress | D6: Atasan Wanita | E6: 599000 | F6: 192 | G6: Senja Wear | H6: Polyester | I6: 3.5
A7: PRD006 | B7: Celana Kulot Tropika Style | C7: Pants | D7: Bawahan Wanita | E7: 119000 | F7: 193 | G7: Tropika Style | H7: Polyester | I7: 4.9
A8: PRD007 | B8: T-Shirt Graphic Cendana Co | C8: Kaos | D8: Atasan Wanita | E8: 119000 | F8: 1 | G8: Cendana Co | H8: Rayon | I8: 4.9
A9: PRD008 | B9: Jaket Bomber Senja Wear | C9: Jaket | D9: Outwear | E9: 549000 | F9: 222 | G9: Senja Wear | H9: Denim | I9: 3.9
A10: PRD009 | B10: Kaos Striped Riang Apparel | C10: T-Shirt | D10: Atasan Pria | E10: 499000 | F10: 41 | G10: Riang Apparel | H10: Twill | I10: 4.7
A11: PRD010 | B11: Kaos Raglan BajuKita | C11: kaos | D11: Atasan Pria | E11: 99000 | F11: 414 | G11: BajuKita | H11: Cotton Combed 30s | I11: 3.6
A12: PRD011 | B12: Topi Baseball Cendana Co | C12: Aksesoris | D12: Aksesoris | E12: 149000 | F12: 370 | G12: Cendana Co | H12: Rayon | I12: 4.8
A13: PRD012 | B13: Kemeja Batik NusaBrand | C13: Shirt | D13: Atasan Wanita | E13: 599000 | F13: 26 | G13: NusaBrand | H13: Twill | I13: 3.7
... A25: PRD024 | B25: Kemeja Linen Tropika Style | C25: Shirt | D25: Atasan Pria | E25: 149000 | F25: 37 | G25: Tropika Style | H25: Polyester | I25: 4.9
A26: PRD025 | B26: Jacket Denim Kanvas Lokal | C26: Jaket | D26: Outwear | E26: 59000 | F26: 272 | G26: Kanvas Lokal | I26: 4.1
A27: PRD026 | B27: Dress Mini Casual BajuKita | C27: Dress | D27: Atasan Wanita | E27: 179000 | F27: 20 | G27: BajuKita | H27: Linen | I27: 4.2
A28: PRD027 | B28: Dompet Kulit Cendana Co | C28: Aksesoris | D28: Aksesoris | E28: 229000 | F28: 1 | G28: Cendana Co | H28: Katun Bambu | I28: 4.3
A29: PRD028 | B29: Dress Bodycon Tropika Style | C29: Dress | D29: Atasan Wanita | E29: 299000 | F29: 112 | G29: Tropika Style | H29: Rayon | I29: 4.6
A30: PRD029 | B30: Shirt Slim Fit Tropika Style | C30: kemeja | D30: Atasan Wanita | E30: 499000 | F30: 26 | G30: Tropika Style | H30: Drill | I30: 3.5
A31: PRD030 | B31: Jaket Hoodie Kanvas Lokal | C31: Jaket | D31: Outwear | E31: 199000 | F31: 403 | G31: Kanvas Lokal | H31: Linen | I31: 3.7
A32: PRD031 | B32: Shirt Slim Fit Tropika Style | C32: Kemeja | D32: Atasan Pria | E32: 69000 | F32: 148 | G32: Tropika Style | H32: Denim | I32: 4
A33: PRD032 | B33: Ikat Pinggang Kulit Tropika Style | C33: Accessories | D33: Aksesoris | E33: 99000 | F33: 464 | G33: Tropika Style | H33: Katun Bambu | I33: 4.7
A34: PRD033 | B34: Celana Chino BajuKita | C34: Celana | D34: Bawahan Wanita | E34: 199000 | F34: 197 | G34: BajuKita | H34: Katun Bambu | I34: 3.5
A35: PRD034 | B35: Topi Baseball Senja Wear | C35: Accessories | D35: Aksesoris | E35: 279000 | F35: 79 | G35: Senja Wear | H35: Katun Bambu | I35: 4.6
A36: PRD035 | B36: Jacket Denim Tropika Style | C36: Jacket | D36: Outwear | E36: 399000 | F36: 49 | G36: Tropika Style | H36: Rayon | I36: 4.9
A37: PRD036 | B37: Syal Rajut Pesona Indo | C37: Accessories | D37: Aksesoris | E37: 299000 | F37: 28 | G37: Pesona Indo | H37: Cotton Combed 30s | I37: 4.8
A38: PRD037 | B38: Dress A-Line Kanvas Lokal | C38: dress | D38: Atasan Wanita | E38: 149000 | F38: 136 | G38: Kanvas Lokal | H38: Cotton 100% | I38: 4.3
... A68: PRD067 | B68: Jaket Parasut Riang Apparel | C68: Jacket | D68: Outwear | E68: 549000 | F68: 11 | G68: Riang Apparel | H68: Cotton-Polyester | I68: 3.5
A69: PRD068 | B69: T-Shirt Graphic Ratu Mode | C69: kaos | D69: Atasan Pria | E69: 129000 | F69: 121 | G69: Ratu Mode | I69: 4.2
A70: PRD069 | B70: Jacket Coach Ratu Mode | C70: Jaket | D70: Outwear | E70: 229000 | F70: 58 | G70: Ratu Mode | H70: Rayon | I70: 4.3
A71: PRD070 | B71: Celana Cargo Pesona Indo | C71: Celana | D71: Bawahan Pria | E71: 349000 | F71: 112 | G71: Pesona Indo | H71: Polyester | I71: 4.5
A72: PRD071 | B72: Dompet Kulit Riang Apparel | C72: Aksesoris | D72: Aksesoris | E72: 99000 | F72: 3 | G72: Riang Apparel | H72: Linen | I72: 4.6
A73: PRD072 | B73: Kaos Polos Basic Ratu Mode | C73: Kaos | D73: Atasan Wanita | E73: 129000 | F73: 199 | G73: Ratu Mode | H73: Cotton Combed 30s | I73: 4.3
A74: PRD073 | B74: Kaos Oversize Riang Apparel | C74: kaos | D74: Atasan Pria | E74: 79000 | F74: 29 | G74: Riang Apparel | H74: Twill | I74: 4.4
A75: PRD074 | B75: Jaket Varsity NusaBrand | C75: Jacket | D75: Outwear | E75: 449000 | F75: 78 | G75: NusaBrand | H75: Linen | I75: 4.4
A76: PRD075 | B76: Ikat Pinggang Kulit Tropika Style | C76: Accessories | D76: Aksesoris | E76: 499000 | F76: 18 | G76: Tropika Style | H76: Katun Bambu | I76: 4.3
A77: PRD076 | B77: Syal Rajut Ratu Mode | C77: Accessories | D77: Aksesoris | E77: 199000 | F77: 18 | G77: Ratu Mode | H77: Katun Bambu | I77: 3.7
A78: PRD077 | B78: Shirt Slim Fit Cendana Co | C78: kemeja | D78: Atasan Pria | E78: 329000 | F78: 32 | G78: Cendana Co | H78: Cotton-Polyester | I78: 4.5
A79: PRD078 | B79: Kaos Striped Cendana Co | C79: kaos | D79: Atasan Wanita | E79: 99000 | F79: 13 | G79: Cendana Co | H79: Twill | I79: 4
A80: PRD079 | B80: Jacket Coach Senja Wear | C80: Jacket | D80: Outwear | E80: 499000 | F80: 14 | G80: Senja Wear | H80: Linen | I80: 4.6
...

Sheet 4. products_clean.csv
A1: product_id | B1: name | C1: category | D1: category_clean | E1: sub_category | F1: price_idr | G1: stock | H1: brand | I1: material | J1: avg_rating
A2: PRD001 | B2: Dress Bodycon Pesona Indo | C2: dress | D2: =VLOOKUP(C2, mapping_kategori!A:B, 2, false) -> Dress | E2: Atasan Wanita | F2: 599000 | G2: 0 | H2: Pesona Indo | I2: Linen | J2: 5
A3: PRD002 | B3: Kaos Oversize BajuKita | C3: T-Shirt | D3: =VLOOKUP(C3, mapping_kategori!A:B, 2, false) -> T-Shirt | E3: Atasan Pria | F3: 329000 | G3: 239 | H3: BajuKita | I3: Cotton 100% | J3: 3.7
A4: PRD003 | B4: Dress Maxi Polos Senja Wear | C4: dress | D4: =VLOOKUP(C4, mapping_kategori!A:B, 2, false) -> Dress | E4: Atasan Wanita | F4: 349000 | G4: 80 | H4: Senja Wear | I4: Cotton-Polyester | J4: 4.7
A5: PRD004 | B5: Ikat Pinggang Kulit Cendana Co | C5: Accessories | D5: =VLOOKUP(C5, mapping_kategori!A:B, 2, false) -> Accessories | E5: Aksesoris | F5: 199000 | G5: 309 | H5: Cendana Co | I5: Denim | J5: 4.6
A6: PRD005 | B6: Dress Bodycon Senja Wear | C6: dress | D6: =VLOOKUP(C6, mapping_kategori!A:B, 2, false) -> Dress | E6: Atasan Wanita | F6: 599000 | G6: 192 | H6: Senja Wear | I6: Polyester | J6: 3.5
A7: PRD006 | B7: Celana Kulot Tropika Style | C7: Pants | D7: =VLOOKUP(C7, mapping_kategori!A:B, 2, false) -> Pants | E7: Bawahan Wanita | F7: 119000 | G7: 193 | H7: Tropika Style | I7: Polyester | J7: 4.9
A8: PRD007 | B8: T-Shirt Graphic Cendana Co | C8: Kaos | D8: =VLOOKUP(C8, mapping_kategori!A:B, 2, false) -> T-Shirt | E8: Atasan Wanita | F8: 119000 | G8: 1 | H8: Cendana Co | I8: Rayon | J8: 4.9
A9: PRD008 | B9: Jaket Bomber Senja Wear | C9: Jaket | D9: =VLOOKUP(C9, mapping_kategori!A:B, 2, false) -> Jacket | E9: Outwear | F9: 549000 | G9: 222 | H9: Senja Wear | I9: Denim | J9: 3.9
A10: PRD009 | B10: Kaos Striped Riang Apparel | C10: T-Shirt | D10: =VLOOKUP(C10, mapping_kategori!A:B, 2, false) -> T-Shirt | E10: Atasan Pria | F10: 499000 | G10: 41 | H10: Riang Apparel | I10: Twill | J10: 4.7
A11: PRD010 | B11: Kaos Raglan BajuKita | C11: kaos | D11: =VLOOKUP(C11, mapping_kategori!A:B, 2, false) -> T-Shirt | E11: Atasan Pria | F11: 99000 | G11: 414 | H11: BajuKita | I11: Cotton Combed 30s | J11: 3.6
A12: PRD011 | B12: Topi Baseball Cendana Co | C12: Aksesoris | D12: =VLOOKUP(C12, mapping_kategori!A:B, 2, false) -> Accessories | E12: Aksesoris | F12: 149000 | G12: 370 | H12: Cendana Co | I12: Rayon | J12: 4.8
A13: PRD012 | B13: Kemeja Batik NusaBrand | C13: Shirt | D13: =VLOOKUP(C13, mapping_kategori!A:B, 2, false) -> Shirt | E13: Atasan Wanita | F13: 599000 | G13: 26 | H13: NusaBrand | I13: Twill | J13: 3.7
... A25: PRD024 | B25: Kemeja Linen Tropika Style | C25: Shirt | D25: =VLOOKUP(C25, mapping_kategori!A:B, 2, false) -> Shirt | E25: Atasan Pria | F25: 149000 | G25: 37 | H25: Tropika Style | I25: Polyester | J25: 4.9
A26: PRD025 | B26: Jacket Denim Kanvas Lokal | C26: Jaket | D26: =VLOOKUP(C26, mapping_kategori!A:B, 2, false) -> Jacket | E26: Outwear | F26: 59000 | G26: 272 | H26: Kanvas Lokal | J26: 4.1
A27: PRD026 | B27: Dress Mini Casual BajuKita | C27: Dress | D27: =VLOOKUP(C27, mapping_kategori!A:B, 2, false) -> Dress | E27: Atasan Wanita | F27: 179000 | G27: 20 | H27: BajuKita | I27: Linen | J27: 4.2
A28: PRD027 | B28: Dompet Kulit Cendana Co | C28: Aksesoris | D28: =VLOOKUP(C28, mapping_kategori!A:B, 2, false) -> Accessories | E28: Aksesoris | F28: 229000 | G28: 1 | H28: Cendana Co | I28: Katun Bambu | J28: 4.3
A29: PRD028 | B29: Dress Bodycon Tropika Style | C29: Dress | D29: =VLOOKUP(C29, mapping_kategori!A:B, 2, false) -> Dress | E29: Atasan Wanita | F29: 299000 | G29: 112 | H29: Tropika Style | I29: Rayon | J29: 4.6
A30: PRD029 | B30: Shirt Slim Fit Tropika Style | C30: kemeja | D30: =VLOOKUP(C30, mapping_kategori!A:B, 2, false) -> Shirt | E30: Atasan Wanita | F30: 499000 | G30: 26 | H30: Tropika Style | I30: Drill | J30: 3.5
A31: PRD030 | B31: Jaket Hoodie Kanvas Lokal | C31: Jaket | D31: =VLOOKUP(C31, mapping_kategori!A:B, 2, false) -> Jacket | E31: Outwear | F31: 199000 | G31: 403 | H31: Kanvas Lokal | I31: Linen | J31: 3.7
A32: PRD031 | B32: Shirt Slim Fit Tropika Style | C32: Kemeja | D32: =VLOOKUP(C32, mapping_kategori!A:B, 2, false) -> Shirt | E32: Atasan Pria | F32: 69000 | G32: 148 | H32: Tropika Style | I32: Denim | J32: 4
A33: PRD032 | B33: Ikat Pinggang Kulit Tropika Style | C33: Accessories | D33: =VLOOKUP(C33, mapping_kategori!A:B, 2, false) -> Accessories | E33: Aksesoris | F33: 99000 | G33: 464 | H33: Tropika Style | I33: Katun Bambu | J33: 4.7
A34: PRD033 | B34: Celana Chino BajuKita | C34: Celana | D34: =VLOOKUP(C34, mapping_kategori!A:B, 2, false) -> Pants | E34: Bawahan Wanita | F34: 199000 | G34: 197 | H34: BajuKita | I34: Katun Bambu | J34: 3.5
A35: PRD034 | B35: Topi Baseball Senja Wear | C35: Accessories | D35: =VLOOKUP(C35, mapping_kategori!A:B, 2, false) -> Accessories | E35: Aksesoris | F35: 279000 | G35: 79 | H35: Senja Wear | I35: Katun Bambu | J35: 4.6
A36: PRD035 | B36: Jacket Denim Tropika Style | C36: Jacket | D36: =VLOOKUP(C36, mapping_kategori!A:B, 2, false) -> Jacket | E36: Outwear | F36: 399000 | G36: 49 | H36: Tropika Style | I36: Rayon | J36: 4.9
A37: PRD036 | B37: Syal Rajut Pesona Indo | C37: Accessories | D37: =VLOOKUP(C37, mapping_kategori!A:B, 2, false) -> Accessories | E37: Aksesoris | F37: 299000 | G37: 28 | H37: Pesona Indo | I37: Cotton Combed 30s | J37: 4.8
A38: PRD037 | B38: Dress A-Line Kanvas Lokal | C38: dress | D38: =VLOOKUP(C38, mapping_kategori!A:B, 2, false) -> Dress | E38: Atasan Wanita | F38: 149000 | G38: 136 | H38: Kanvas Lokal | I38: Cotton 100% | J38: 4.3
... A68: PRD067 | B68: Jaket Parasut Riang Apparel | C68: Jacket | D68: =VLOOKUP(C68, mapping_kategori!A:B, 2, false) -> Jacket | E68: Outwear | F68: 549000 | G68: 11 | H68: Riang Apparel | I68: Cotton-Polyester | J68: 3.5
A69: PRD068 | B69: T-Shirt Graphic Ratu Mode | C69: kaos | D69: =VLOOKUP(C69, mapping_kategori!A:B, 2, false) -> T-Shirt | E69: Atasan Pria | F69: 129000 | G69: 121 | H69: Ratu Mode | J69: 4.2
A70: PRD069 | B70: Jacket Coach Ratu Mode | C70: Jaket | D70: =VLOOKUP(C70, mapping_kategori!A:B, 2, false) -> Jacket | E70: Outwear | F70: 229000 | G70: 58 | H70: Ratu Mode | I70: Rayon | J70: 4.3
A71: PRD070 | B71: Celana Cargo Pesona Indo | C71: Celana | D71: =VLOOKUP(C71, mapping_kategori!A:B, 2, false) -> Pants | E71: Bawahan Pria | F71: 349000 | G71: 112 | H71: Pesona Indo | I71: Polyester | J71: 4.5
A72: PRD071 | B72: Dompet Kulit Riang Apparel | C72: Aksesoris | D72: =VLOOKUP(C72, mapping_kategori!A:B, 2, false) -> Accessories | E72: Aksesoris | F72: 99000 | G72: 3 | H72: Riang Apparel | I72: Linen | J72: 4.6
A73: PRD072 | B73: Kaos Polos Basic Ratu Mode | C73: Kaos | D73: =VLOOKUP(C73, mapping_kategori!A:B, 2, false) -> T-Shirt | E73: Atasan Wanita | F73: 129000 | G73: 199 | H73: Ratu Mode | I73: Cotton Combed 30s | J73: 4.3
A74: PRD073 | B74: Kaos Oversize Riang Apparel | C74: kaos | D74: =VLOOKUP(C74, mapping_kategori!A:B, 2, false) -> T-Shirt | E74: Atasan Pria | F74: 79000 | G74: 29 | H74: Riang Apparel | I74: Twill | J74: 4.4
A75: PRD074 | B75: Jaket Varsity NusaBrand | C75: Jacket | D75: =VLOOKUP(C75, mapping_kategori!A:B, 2, false) -> Jacket | E75: Outwear | F75: 449000 | G75: 78 | H75: NusaBrand | I75: Linen | J75: 4.4
A76: PRD075 | B76: Ikat Pinggang Kulit Tropika Style | C76: Accessories | D76: =VLOOKUP(C76, mapping_kategori!A:B, 2, false) -> Accessories | E76: Aksesoris | F76: 499000 | G76: 18 | H76: Tropika Style | I76: Katun Bambu | J76: 4.3
A77: PRD076 | B77: Syal Rajut Ratu Mode | C77: Accessories | D77: =VLOOKUP(C77, mapping_kategori!A:B, 2, false) -> Accessories | E77: Aksesoris | F77: 199000 | G77: 18 | H77: Ratu Mode | I77: Katun Bambu | J77: 3.7
A78: PRD077 | B78: Shirt Slim Fit Cendana Co | C78: kemeja | D78: =VLOOKUP(C78, mapping_kategori!A:B, 2, false) -> Shirt | E78: Atasan Pria | F78: 329000 | G78: 32 | H78: Cendana Co | I78: Cotton-Polyester | J78: 4.5
A79: PRD078 | B79: Kaos Striped Cendana Co | C79: kaos | D79: =VLOOKUP(C79, mapping_kategori!A:B, 2, false) -> T-Shirt | E79: Atasan Wanita | F79: 99000 | G79: 13 | H79: Cendana Co | I79: Twill | J79: 4
A80: PRD079 | B80: Jacket Coach Senja Wear | C80: Jacket | D80: =VLOOKUP(C80, mapping_kategori!A:B, 2, false) -> Jacket | E80: Outwear | F80: 499000 | G80: 14 | H80: Senja Wear | I80: Linen | J80: 4.6
...

Sheet Data_Master
A1: order_id | B1: product_id | C1: quantity | D1: subtotal_idr | E1: order_date | F1: order_status | G1: is_lost_revenue | H1: shipping_city | I1: shipping_province | J1: category_clean
A2: ORD000001 | B2: PRD070 | C2: 1 | D2: 349000 | E2: {=_xlfn.XLOOKUP(A2, '3. orders_clean.csv'!A:A,'3. orders_clean.csv'!C:C)} -> 45008 | F2: {=_xlfn.XLOOKUP(A2, '3. orders_clean.csv'!A:A, '3. orders_clean.csv'!I:I)} -> shipped | G2: {=_xlfn.XLOOKUP(A2, '3. orders_clean.csv'!A:A, '3. orders_clean.csv'!J:J)} -> FALSE | H2: {=_xlfn.XLOOKUP(A2, '3. orders_clean.csv'!A:A, '3. orders_clean.csv'!E:E)} -> Banjarmasin | I2: {=_xlfn.XLOOKUP(A2, '3. orders_clean.csv'!A:A, '3. orders_clean.csv'!F:F)} -> Kalimantan Selatan | J2: {=_xlfn.XLOOKUP(B:B, '4. products_clean.csv'!A:A, '4. products_clean.csv'!D:D)} -> Pants
A3: ORD000001 | B3: PRD001 | C3: 2 | D3: 1198000 | E3: {=_xlfn.XLOOKUP(A3, '3. orders_clean.csv'!A:A,'3. orders_clean.csv'!C:C)} -> 45008 | F3: {=_xlfn.XLOOKUP(A3, '3. orders_clean.csv'!A:A, '3. orders_clean.csv'!I:I)} -> shipped | G3: {=_xlfn.XLOOKUP(A3, '3. orders_clean.csv'!A:A, '3. orders_clean.csv'!J:J)} -> FALSE | H3: {=_xlfn.XLOOKUP(A3, '3. orders_clean.csv'!A:A, '3. orders_clean.csv'!E:E)} -> Banjarmasin | I3: {=_xlfn.XLOOKUP(A3, '3. orders_clean.csv'!A:A, '3. orders_clean.csv'!F:F)} -> Kalimantan Selatan | J3: {=_xlfn.XLOOKUP(B:B, '4. products_clean.csv'!A:A, '4. products_clean.csv'!D:D)} -> Dress
A4: ORD000001 | B4: PRD148 | C4: 1 | D4: 449000 | E4: {=_xlfn.XLOOKUP(A4, '3. orders_clean.csv'!A:A,'3. orders_clean.csv'!C:C)} -> 45008 | F4: {=_xlfn.XLOOKUP(A4, '3. orders_clean.csv'!A:A, '3. orders_clean.csv'!I:I)} -> shipped | G4: {=_xlfn.XLOOKUP(A4, '3. orders_clean.csv'!A:A, '3. orders_clean.csv'!J:J)} -> FALSE | H4: {=_xlfn.XLOOKUP(A4, '3. orders_clean.csv'!A:A, '3. orders_clean.csv'!E:E)} -> Banjarmasin | I4: {=_xlfn.XLOOKUP(A4, '3. orders_clean.csv'!A:A, '3. orders_clean.csv'!F:F)} -> Kalimantan Selatan | J4: {=_xlfn.XLOOKUP(B:B, '4. products_clean.csv'!A:A, '4. products_clean.csv'!D:D)} -> T-Shirt
A5: ORD000002 | B5: PRD086 | C5: 1 | D5: 329000 | E5: {=_xlfn.XLOOKUP(A5, '3. orders_clean.csv'!A:A,'3. orders_clean.csv'!C:C)} -> 45714 | F5: {=_xlfn.XLOOKUP(A5, '3. orders_clean.csv'!A:A, '3. orders_clean.csv'!I:I)} -> delivered | G5: {=_xlfn.XLOOKUP(A5, '3. orders_clean.csv'!A:A, '3. orders_clean.csv'!J:J)} -> FALSE | H5: {=_xlfn.XLOOKUP(A5, '3. orders_clean.csv'!A:A, '3. orders_clean.csv'!E:E)} -> Palembang | I5: {=_xlfn.XLOOKUP(A5, '3. orders_clean.csv'!A:A, '3. orders_clean.csv'!F:F)} -> Sumatera Selatan | J5: {=_xlfn.XLOOKUP(B:B, '4. products_clean.csv'!A:A, '4. products_clean.csv'!D:D)} -> Pants
A6: ORD000002 | B6: PRD258 | C6: 1 | D6: 129000 | E6: {=_xlfn.XLOOKUP(A6, '3. orders_clean.csv'!A:A,'3. orders_clean.csv'!C:C)} -> 45714 | F6: {=_xlfn.XLOOKUP(A6, '3. orders_clean.csv'!A:A, '3. orders_clean.csv'!I:I)} -> delivered | G6: {=_xlfn.XLOOKUP(A6, '3. orders_clean.csv'!A:A, '3. orders_clean.csv'!J:J)} -> FALSE | H6: {=_xlfn.XLOOKUP(A6, '3. orders_clean.csv'!A:A, '3. orders_clean.csv'!E:E)} -> Palembang | I6: {=_xlfn.XLOOKUP(A6, '3. orders_clean.csv'!A:A, '3. orders_clean.csv'!F:F)} -> Sumatera Selatan | J6: {=_xlfn.XLOOKUP(B:B, '4. products_clean.csv'!A:A, '4. products_clean.csv'!D:D)} -> Accessories
A7: ORD000002 | B7: PRD256 | C7: 1 | D7: 49000 | E7: {=_xlfn.XLOOKUP(A7, '3. orders_clean.csv'!A:A,'3. orders_clean.csv'!C:C)} -> 45714 | F7: {=_xlfn.XLOOKUP(A7, '3. orders_clean.csv'!A:A, '3. orders_clean.csv'!I:I)} -> delivered | G7: {=_xlfn.XLOOKUP(A7, '3. orders_clean.csv'!A:A, '3. orders_clean.csv'!J:J)} -> FALSE | H7: {=_xlfn.XLOOKUP(A7, '3. orders_clean.csv'!A:A, '3. orders_clean.csv'!E:E)} -> Palembang | I7: {=_xlfn.XLOOKUP(A7, '3. orders_clean.csv'!A:A, '3. orders_clean.csv'!F:F)} -> Sumatera Selatan | J7: {=_xlfn.XLOOKUP(B:B, '4. products_clean.csv'!A:A, '4. products_clean.csv'!D:D)} -> Dress
A8: ORD000003 | B8: PRD076 | C8: 1 | D8: 199000 | E8: {=_xlfn.XLOOKUP(A8, '3. orders_clean.csv'!A:A,'3. orders_clean.csv'!C:C)} -> 44755 | F8: {=_xlfn.XLOOKUP(A8, '3. orders_clean.csv'!A:A, '3. orders_clean.csv'!I:I)} -> delivered | G8: {=_xlfn.XLOOKUP(A8, '3. orders_clean.csv'!A:A, '3. orders_clean.csv'!J:J)} -> FALSE | H8: {=_xlfn.XLOOKUP(A8, '3. orders_clean.csv'!A:A, '3. orders_clean.csv'!E:E)} -> Tangerang | I8: {=_xlfn.XLOOKUP(A8, '3. orders_clean.csv'!A:A, '3. orders_clean.csv'!F:F)} -> Banten | J8: {=_xlfn.XLOOKUP(B:B, '4. products_clean.csv'!A:A, '4. products_clean.csv'!D:D)} -> Accessories
A9: ORD000004 | B9: PRD205 | C9: 1 | D9: 119000 | E9: {=_xlfn.XLOOKUP(A9, '3. orders_clean.csv'!A:A,'3. orders_clean.csv'!C:C)} -> 45622 | F9: {=_xlfn.XLOOKUP(A9, '3. orders_clean.csv'!A:A, '3. orders_clean.csv'!I:I)} -> cancelled | G9: {=_xlfn.XLOOKUP(A9, '3. orders_clean.csv'!A:A, '3. orders_clean.csv'!J:J)} -> TRUE | H9: {=_xlfn.XLOOKUP(A9, '3. orders_clean.csv'!A:A, '3. orders_clean.csv'!E:E)} -> Medan | I9: {=_xlfn.XLOOKUP(A9, '3. orders_clean.csv'!A:A, '3. orders_clean.csv'!F:F)} -> Sumatera Utara | J9: {=_xlfn.XLOOKUP(B:B, '4. products_clean.csv'!A:A, '4. products_clean.csv'!D:D)} -> Accessories
A10: ORD000005 | B10: PRD239 | C10: 2 | D10: 358000 | E10: {=_xlfn.XLOOKUP(A10, '3. orders_clean.csv'!A:A,'3. orders_clean.csv'!C:C)} -> 45138 | F10: {=_xlfn.XLOOKUP(A10, '3. orders_clean.csv'!A:A, '3. orders_clean.csv'!I:I)} -> cancelled | G10: {=_xlfn.XLOOKUP(A10, '3. orders_clean.csv'!A:A, '3. orders_clean.csv'!J:J)} -> TRUE | H10: {=_xlfn.XLOOKUP(A10, '3. orders_clean.csv'!A:A, '3. orders_clean.csv'!E:E)} -> Bandung | I10: {=_xlfn.XLOOKUP(A10, '3. orders_clean.csv'!A:A, '3. orders_clean.csv'!F:F)} -> Jawa Barat | J10: {=_xlfn.XLOOKUP(B:B, '4. products_clean.csv'!A:A, '4. products_clean.csv'!D:D)} -> Jacket
A11: ORD000006 | B11: PRD170 | C11: 1 | D11: 349000 | E11: {=_xlfn.XLOOKUP(A11, '3. orders_clean.csv'!A:A,'3. orders_clean.csv'!C:C)} -> 44693 | F11: {=_xlfn.XLOOKUP(A11, '3. orders_clean.csv'!A:A, '3. orders_clean.csv'!I:I)} -> returned | G11: {=_xlfn.XLOOKUP(A11, '3. orders_clean.csv'!A:A, '3. orders_clean.csv'!J:J)} -> TRUE | H11: {=_xlfn.XLOOKUP(A11, '3. orders_clean.csv'!A:A, '3. orders_clean.csv'!E:E)} -> Balikpapan | I11: {=_xlfn.XLOOKUP(A11, '3. orders_clean.csv'!A:A, '3. orders_clean.csv'!F:F)} -> Kalimantan Timur | J11: {=_xlfn.XLOOKUP(B:B, '4. products_clean.csv'!A:A, '4. products_clean.csv'!D:D)} -> Shirt
A12: ORD000007 | B12: PRD013 | C12: 1 | D12: 149000 | E12: {=_xlfn.XLOOKUP(A12, '3. orders_clean.csv'!A:A,'3. orders_clean.csv'!C:C)} -> 44597 | F12: {=_xlfn.XLOOKUP(A12, '3. orders_clean.csv'!A:A, '3. orders_clean.csv'!I:I)} -> delivered | G12: {=_xlfn.XLOOKUP(A12, '3. orders_clean.csv'!A:A, '3. orders_clean.csv'!J:J)} -> FALSE | H12: {=_xlfn.XLOOKUP(A12, '3. orders_clean.csv'!A:A, '3. orders_clean.csv'!E:E)} -> Bekasi | I12: {=_xlfn.XLOOKUP(A12, '3. orders_clean.csv'!A:A, '3. orders_clean.csv'!F:F)} -> Jawa Barat | J12: {=_xlfn.XLOOKUP(B:B, '4. products_clean.csv'!A:A, '4. products_clean.csv'!D:D)} -> Pants
A13: ORD000007 | B13: PRD230 | C13: 2 | D13: 258000 | E13: {=_xlfn.XLOOKUP(A13, '3. orders_clean.csv'!A:A,'3. orders_clean.csv'!C:C)} -> 44597 | F13: {=_xlfn.XLOOKUP(A13, '3. orders_clean.csv'!A:A, '3. orders_clean.csv'!I:I)} -> delivered | G13: {=_xlfn.XLOOKUP(A13, '3. orders_clean.csv'!A:A, '3. orders_clean.csv'!J:J)} -> FALSE | H13: {=_xlfn.XLOOKUP(A13, '3. orders_clean.csv'!A:A, '3. orders_clean.csv'!E:E)} -> Bekasi | I13: {=_xlfn.XLOOKUP(A13, '3. orders_clean.csv'!A:A, '3. orders_clean.csv'!F:F)} -> Jawa Barat | J13: {=_xlfn.XLOOKUP(B:B, '4. products_clean.csv'!A:A, '4. products_clean.csv'!D:D)} -> Accessories
... A4987: ORD003000 | B4987: PRD117 | C4987: 1 | D4987: 49000 | E4987: {=_xlfn.XLOOKUP(A4987, '3. orders_clean.csv'!A:A,'3. orders_clean.csv'!C:C)} -> 45434 | F4987: {=_xlfn.XLOOKUP(A4987, '3. orders_clean.csv'!A:A, '3. orders_clean.csv'!I:I)} -> returned | G4987: {=_xlfn.XLOOKUP(A4987, '3. orders_clean.csv'!A:A, '3. orders_clean.csv'!J:J)} -> TRUE | H4987: {=_xlfn.XLOOKUP(A4987, '3. orders_clean.csv'!A:A, '3. orders_clean.csv'!E:E)} -> Depok | I4987: {=_xlfn.XLOOKUP(A4987, '3. orders_clean.csv'!A:A, '3. orders_clean.csv'!F:F)} -> Jawa Barat | J4987: {=_xlfn.XLOOKUP(B:B, '4. products_clean.csv'!A:A, '4. products_clean.csv'!D:D)} -> Jacket

Sheet 5. reviews.csv
A1: review_id | B1: order_id | C1: product_id | D1: customer_id | E1: rating | F1: review_text | G1: review_date | H1: helpful_count
A2: REV00001 | B2: ORD000131 | C2: PRD269 | D2: CUST0714 | E2: 3 | F2: Bahan premium, jahitan kuat. | G2: 45338 | H2: 0
A3: REV00002 | B3: ORD001162 | C3: PRD105 | D3: CUST0586 | E3: 2 | F3: Bagus banget, packaging juga aman. | G3: 45681 | H3: 0
A4: REV00003 | B4: ORD001172 | C4: PRD053 | D4: CUST0164 | E4: 5 | F4: Modelnya keren, fit di badan. | G4: 45553 | H4: 18
A5: REV00004 | B5: ORD002879 | C5: PRD265 | D5: CUST0179 | E5: 4 | F5: Kualitas oke untuk harga segini. | G5: 45367 | H5: 0
A6: REV00005 | B6: ORD001303 | C6: PRD252 | D6: CUST0606 | E6: 3 | F6: Produk sampai dengan cepat, sesuai ekspektasi. | G6: 45317 | H6: 46
A7: REV00006 | B7: ORD002340 | C7: PRD028 | D7: CUST0465 | E7: 5 | F7: Mantap, langganan terus dari sini. | G7: 45287 | H7: 0
A8: REV00007 | B8: ORD002140 | C8: PRD096 | D8: CUST0616 | E8: 5 | F8: Sesuai deskripsi, akan beli lagi. | G8: 45319 | H8: 0
A9: REV00008 | B9: ORD002124 | C9: PRD023 | D9: CUST0030 | E9: 5 | F9: Wah ini sih murah meriah tapi berkualitas. | G9: 45446 | H9: 11
A10: REV00009 | B10: ORD002964 | C10: PRD181 | D10: CUST0479 | E10: 3 | F10: Produknya bagus tapi pengiriman lama. | G10: 45204 | H10: 0
A11: REV00010 | B11: ORD001442 | C11: PRD072 | D11: CUST0550 | E11: 3 | F11: Modelnya keren, fit di badan. | G11: 45239 | H11: 0
A12: REV00011 | B12: ORD002046 | C12: PRD254 | D12: CUST0488 | E12: 5 | G12: 45460 | H12: 0
A13: REV00012 | B13: ORD001842 | C13: PRD019 | D13: CUST0480 | E13: 4 | F13: Pengiriman cepat, packaging rapi. | G13: 45667 | H13: 6
A14: REV00013 | B14: ORD000293 | C14: PRD150 | D14: CUST0135 | E14: 5 | F14: Suka banget, repeat order pasti. | G14: 44677 | H14: 9
A15: REV00014 | B15: ORD001301 | C15: PRD210 | D15: CUST0141 | E15: 5 | F15: Ukuran agak kekecilan, tapi bahan oke. | G15: 44717 | H15: 11
A16: REV00015 | B16: ORD001293 | C16: PRD270 | D16: CUST0531 | E16: 4 | F16: Pengiriman cepat, packaging rapi. | G16: 44918 | H16: 9
A17: REV00016 | B17: ORD000867 | C17: PRD259 | D17: CUST0270 | E17: 5 | F17: Bagus banget, packaging juga aman. | G17: 45132 | H17: 31
A18: REV00017 | B18: ORD001287 | C18: PRD280 | D18: CUST0048 | E18: 5 | F18: Produk original, terima kasih seller. | G18: 45593 | H18: 0
A19: REV00018 | B19: ORD000965 | C19: PRD102 | D19: CUST0758 | E19: 3 | F19: Jahitannya kurang rapi, tapi masih bisa dipake. | G19: 45595 | H19: 6
A20: REV00019 | B20: ORD000890 | C20: PRD195 | D20: CUST0778 | E20: 5 | F20: Awalnya ragu, ternyata kualitasnya oke. | G20: 45401 | H20: 0
A21: REV00020 | B21: ORD002400 | C21: PRD172 | D21: CUST0417 | E21: 5 | F21: Agak mengecewakan, bahannya panas. | G21: 45210 | H21: 0
A22: REV00021 | B22: ORD002369 | C22: PRD196 | D22: CUST0259 | E22: 5 | F22: Suka banget, repeat order pasti. | G22: 45522 | H22: 3
A23: REV00022 | B23: ORD001470 | C23: PRD297 | D23: CUST0376 | E23: 5 | F23: Warna agak beda dari foto. | G23: 44927 | H23: 0
A24: REV00023 | B24: ORD002158 | C24: PRD213 | D24: CUST0682 | E24: 4 | G24: 45157 | H24: 10
A25: REV00024 | B25: ORD000417 | C25: PRD013 | D25: CUST0527 | E25: 4 | F25: Produk sampai dengan cepat, sesuai ekspektasi. | G25: 45363 | H25: 4
A26: REV00025 | B26: ORD002694 | C26: PRD298 | D26: CUST0293 | E26: 5 | F26: Tidak sesuai ekspektasi, kurang puas. | G26: 45103 | H26: 0
A27: REV00026 | B27: ORD001044 | C27: PRD181 | D27: CUST0226 | E27: 5 | F27: Cocok buat hangout, modelnya kekinian. | G27: 45272 | H27: 10
A28: REV00027 | B28: ORD000043 | C28: PRD009 | D28: CUST0575 | E28: 4 | G28: 45388 | H28: 2
A29: REV00028 | B29: ORD002050 | C29: PRD005 | D29: CUST0521 | E29: 3 | F29: Bahannya enak banget, jahitan rapi. Recommended! | G29: 45675 | H29: 0
A30: REV00029 | B30: ORD000334 | C30: PRD001 | D30: CUST0148 | E30: 5 | F30: Kainnya tipis, agak kecewa. | G30: 44637 | H30: 0
A31: REV00030 | B31: ORD002146 | C31: PRD026 | D31: CUST0354 | E31: 5 | F31: Modelnya simple, gampang di-mix and match. | G31: 44905 | H31: 0
A32: REV00031 | B32: ORD001633 | C32: PRD156 | D32: CUST0573 | E32: 5 | F32: Warna agak beda dari foto. | G32: 45396 | H32: 9
A33: REV00032 | B33: ORD001736 | C33: PRD219 | D33: CUST0160 | E33: 5 | F33: Bahan premium, jahitan kuat. | G33: 44922 | H33: 10
A34: REV00033 | B34: ORD000016 | C34: PRD052 | D34: CUST0441 | E34: 4 | F34: Bagus banget, packaging juga aman. | G34: 45424 | H34: 3
A35: REV00034 | B35: ORD000216 | C35: PRD060 | D35: CUST0177 | E35: 5 | F35: Awalnya ragu, ternyata kualitasnya oke. | G35: 45566 | H35: 0
A36: REV00035 | B36: ORD002501 | C36: PRD113 | D36: CUST0565 | E36: 3 | F36: Kualitas oke untuk harga segini. | G36: 44677 | H36: 0
A37: REV00036 | B37: ORD002750 | C37: PRD298 | D37: CUST0096 | E37: 4 | F37: Bagus banget, packaging juga aman. | G37: 45418 | H37: 6
A38: REV00037 | B38: ORD001607 | C38: PRD275 | D38: CUST0143 | E38: 5 | F38: Bahannya enak banget, jahitan rapi. Recommended! | G38: 44647 | H38: 27
A39: REV00038 | B39: ORD000825 | C39: PRD276 | D39: CUST0218 | E39: 3 | F39: Produk original, terima kasih seller. | G39: 45720 | H39: 0
A40: REV00039 | B40: ORD001079 | C40: PRD195 | D40: CUST0057 | E40: 5 | F40: Bahan premium, jahitan kuat. | G40: 45053 | H40: 0
...

Sheet 5. reviews_clean.csv
A1: review_id | B1: order_id | C1: product_id | D1: customer_id | E1: rating | F1: review_text | G1: review_date | H1: helpful_count
A2: REV00001 | B2: ORD000131 | C2: PRD269 | D2: CUST0714 | E2: 3 | F2: Bahan premium, jahitan kuat. | G2: 45338 | H2: 0
A3: REV00002 | B3: ORD001162 | C3: PRD105 | D3: CUST0586 | E3: 2 | F3: Bagus banget, packaging juga aman. | G3: 45681 | H3: 0
A4: REV00003 | B4: ORD001172 | C4: PRD053 | D4: CUST0164 | E4: 5 | F4: Modelnya keren, fit di badan. | G4: 45553 | H4: 18
A5: REV00004 | B5: ORD002879 | C5: PRD265 | D5: CUST0179 | E5: 4 | F5: Kualitas oke untuk harga segini. | G5: 45367 | H5: 0
A6: REV00005 | B6: ORD001303 | C6: PRD252 | D6: CUST0606 | E6: 3 | F6: Produk sampai dengan cepat, sesuai ekspektasi. | G6: 45317 | H6: 46
A7: REV00006 | B7: ORD002340 | C7: PRD028 | D7: CUST0465 | E7: 5 | F7: Mantap, langganan terus dari sini. | G7: 45287 | H7: 0
A8: REV00007 | B8: ORD002140 | C8: PRD096 | D8: CUST0616 | E8: 5 | F8: Sesuai deskripsi, akan beli lagi. | G8: 45319 | H8: 0
A9: REV00008 | B9: ORD002124 | C9: PRD023 | D9: CUST0030 | E9: 5 | F9: Wah ini sih murah meriah tapi berkualitas. | G9: 45446 | H9: 11
A10: REV00009 | B10: ORD002964 | C10: PRD181 | D10: CUST0479 | E10: 3 | F10: Produknya bagus tapi pengiriman lama. | G10: 45204 | H10: 0
A11: REV00010 | B11: ORD001442 | C11: PRD072 | D11: CUST0550 | E11: 3 | F11: Modelnya keren, fit di badan. | G11: 45239 | H11: 0
A12: REV00011 | B12: ORD002046 | C12: PRD254 | D12: CUST0488 | E12: 5 | F12: Kosong | G12: 45460 | H12: 0
A13: REV00012 | B13: ORD001842 | C13: PRD019 | D13: CUST0480 | E13: 4 | F13: Pengiriman cepat, packaging rapi. | G13: 45667 | H13: 6
... A1501: REV01500 | B1501: ORD002062 | C1501: PRD185 | D1501: CUST0076 | E1501: 4 | F1501: Untuk harga segini, kualitasnya mantap. | G1501: 45451 | H1501: 18

Sheet definisi revenue loss
A1: Definisi Revenue Loss = total nilai order yang cancelled + returned (328 + 151 order dari 3000).

Sheet mapping_kategori
A1: kategori_lama | B1: kategori_baru
A2: {=UNIQUE('4. products_clean.csv'!C:C)} -> category | B2: Kategori
A3: dress | B3: Dress
A4: T-Shirt | B4: T-Shirt
A5: Accessories | B5: Accessories
A6: Pants | B6: Pants
A7: Kaos | B7: T-Shirt
A8: Jaket | B8: Jacket
A9: kaos | B9: T-Shirt
A10: Aksesoris | B10: Accessories
A11: Shirt | B11: Shirt
A12: Celana | B12: Pants
A13: Jacket | B13: Jacket
A14: Dress | B14: Dress
... A16: Kemeja | B16: Shirt
